
引用类型 `Promise` 可以通过 new 操作符来实例化。创建新期约时需要传入执行器(executor)函数作为参数。

### 期约状态机

期约是一个有状态的对象，可能处于如下 3 种状态之一:
- 待定(pending)
- 解决(resolved)
- 拒绝(rejected)

`待定`(pending)是期约的最初状态。在待定状态下，期约可以落定(settled)为代表成功的`解决`(resolved)状态，或者代表失败的`拒绝`(rejected)状态。无论落定为哪种状态都是不可逆的。只要从待定转换为解决或拒绝，期约的状态就不再改变。而且，也不能保证期约必然会脱离待定状态。因此，组织合理的代码无论期约解决(resolve)还是拒绝(reject)，甚至永远处于待定(pending)状态，都应该具有恰当的行为。

期约的状态是私有的，不能直接通过 JavaScript 检测到。`这主要是为了避免根据读取到的期约状态，以同步方式处理期约对象`。也因此，期约的状态也当然不能被外部修改。

### 解决值、拒绝理由及期约用例

期约主要有两大用途。首先是抽象地表示一个异步操作。期约的状态代表期约是否完成。"待定"表示尚未开始或者正在执行中。"解决"表示已经成功完成，而"拒绝"则表示没有成功完成。

在另外一些情况下，期约封装的异步操作会实际生成某个值，而程序期待期约状态改变时可以访问这个值。相应地，如果期约被拒绝，程序就会期待期约状态改变时可以拿到拒绝的理由。

为了支持这两种用例，每个期约只要状态切换为解决，就会有一个私有的内部`值`(value)。类似地，每个期约只要状态切换为拒绝，就会有一个私有的内部`理由`(reason)。无论是值还是理由，都是包含原始值或对象的`不可修改`的引用。二者都是可选的，而且默认值为 undefined。在期约到达某个落定状态时执行的异步代码始终会收到这个值或理由。

### 通过执行函数控制期约状态

由于期约的状态是私有的，所以只能在内部进行操作。内部操作在期约的执行器函数中完成。

执行器函数主要有两项职责: `初始化期约的异步行为`和`控制状态的最终转换`。其中，控制期约状态的转换是通过调用它的两个函数参数实现的。这两个函数参数通常都命名为 `resolve()` 和 `reject()`。调用 resolve() 会把状态切换为解决，调用 reject() 会把状态切换为拒绝。另外，调用 reject() 也会`抛出错误`。

无论 resolve() 和 reject() 中的哪个被调用，状态转换都不可撤销了。于是继续修改状态会静默失败。如下:
```js
    let p = new Promise((resolve, reject) => {
        resolve();
        reject();       // 没有效果
    });
```
为了避免期约卡在待定状态，可以利用上述特性添加一个定时退出功能。比如，可以通过 setTimeout 设置一个 10 秒钟后无论如何都会拒绝期约的回调:
```js
    let p = new Promise((resolve, reject) => {
        setTimeout(reject, 10000);  // 10 秒后调用 reject()
        // 执行函数的逻辑
    });
```
[超时后执行指定动作](t/01_timeout_reject.js)

### Promise.resolve()

期约并非一开始就必须处于待定状态，然后通过执行器函数才能转换为落定状态。通过调用 `Promise.resolve()` 静态方法，可以实例化一个解决的期约。下面两个期约实例实际上是一样的:`
```js
    let p1 = new Promise((resolve, reject) => resolve());
    let p2 = Promise.resolve();
```

这个解决的期约的值对应着传给 Promise.resolve() 的第一个参数。使用这个静态方法，实际上可以把任何值都转换为一个期约:
```js
    setTimeout(console.log, 0, Promise.resolve());  // Promise <resolved>: undefined
    
    setTimeout(console.log, 0, Promise.resolve(3)); // Promise <resolved>: 3

    // 多余的参数会忽略
    setTimeout(console.log, 0, Promise.resolve(4, 5, 6));   // Promise <resolved>: 4
```

对这个静态方法而言，如果传入的参数本身是一个期约，那它的行为就类似于一个空包装。因此，Promise.resolve() 可以说是一个幂等方法:
```js
    let p = Promise.resolve(7);
    
    setTimeout(console.log, 0, p === Promise.resolve(p));   // true

    setTimeout(console.log, 0, p === Promise.resolve(Promise.resolve(p)));
```
[resolve的幂等测试](t/01_resolve_idempotent.js)

由于这个静态方法能够包装任何非期约值，包括错误对象，并将其转换为解决的期约。因此，也可能导致不符合预期的行为:
```js
    let p = Promise.resolve(new Error('foo'));

    setTimeout(console.log, 0, p);  // Promise <resolved>: Error: foo
```

### Promise.reject()

与 Promise.resolve() 类似，Promise.reject() 会实例化一个拒绝的期约并抛出一个异步错误。

下面的两个期约实例实际上是一样的:
```js
    let p1 = new Promise((resolve, reject) => reject());
    let p2 = Promise.reject();
```
这个拒绝的期约的理由就是传给 Promise.reject() 的第一个参数。这个参数也会传给后续的拒绝处理程序:
```js
    let p = Promise.reject(3);

    setTimeout(console.log, 0, p);  // Promise <rejected>: 3

    p.then(null, (e) => setTimeout(console.log, 0, e)); // 3
```
[在哪里捕获](t/01_reject.js)

Promise.reject() 并没有照搬 Promise.resolve() 的幂等逻辑。如果给它传一个期约对象，则这个期约会成为它返回的拒绝期约的理由:
```js
    setTimeout(console.log, 0, Promise.reject(Promise.resolve()));  // Promise <rejected>: Promise <resolved>
```

注意，Promise.reject() 抛出的错误不能通过 try/catch 捕获，而只能通过拒绝处理程序捕获。这是因为 try/catch 是对同步代码进行捕获，而异步错误是通过消息队列来处理的。
```js
    try {
        throw new Error('foo');
    } catch(e) {
        console.log(e);     // Error: foo
    }

    try {
        Promise.reject(new Error('bar'));
    } catch(e) {
        console.log(e);
    }
    // uncaught (in promise) Error: bar
```
[同步异步异常错误捕获对比](t/01_reject_catch.js)
